Workbook

Sheet d20-pmt
A1: City of Tampa – Schedule of All To-Be-Utilized Sub-(Contractors/Consultants/Suppliers)
A2: DMI-20 Form | Page 1 of 2 – DMI Solicited/Utilized Schedules
A4: Contract No.: | B4: 25-P-00039 | C4: Contract Name: | D4: Job Order for Residential Rehabilitation and Repair Services
A5: Company Name: | B5: Lionize Construction | C5: Address: | D5: 38439 5th Avenue, PMB 128, Zephyrhills, FL 33542
A6: Federal ID: | B6: 264346308 | C6: Phone: | D6: 407-466-3689 | E6: Email: | F6: Luz@aioenterprise.com
A7: Property Address: | B7: 3610 E Dr Martin Luther King Jr Blvd, Tampa, FL 33610
A8: Note: Form DMI-20 must list ALL subcontractors To-Be-Utilized.
A9: S/O Federal ID | B9: Company Name Address Phone / Fax / Email | C9: Trade, Services or Materials | D9: NIGP Code | E9: $ Amount of Quote / Letter of Intent (LOI) | F9: % of Scope or Contract | G9: SLBE Certified? | H9: Pmt1 | I9: Pmt2 | J9: pmt 3 | K9: Total
B10: City of Tampa - Development & Growth | C10: Buildings / Permits | D10: 909 | E10: 1541.78 | F10: =+E10/$E$22 -> 0.012348943 | G10: N/A | H10: =+E10 -> 1541.78 | K10: =SUM(H10:J10) -> 1541.78
B11: Hillsborough County | C11: Buildings / Permits | D11: 909 | E11: 13.46 | F11: =+E11/$E$22 -> 0.00010780836 | G11: N/A | H11: =+E11 -> 13.46 | K11: =SUM(H11:J11) -> 13.46
A12: S 86-3095308 | B12: Ambit Engineering, LLC 3848 Sun City Center Blvd Ste 104 PMB 1027 Ruskin, FL 33573 | C12: Engineers & Surveyors | D12: 925 | E12: 660 | F12: =+E12/$E$22 -> 0.0052862941 | G12: Yes | H12: =+E12 -> 660 | K12: =SUM(H12:J12) -> 660
A13: O 88-1849350 | B13: JM Drafting Services LLC 9944 Warm Stone Street Thonotosassa, FL 33592 | C13: Engineers & Surveyors | D13: 925 | E13: 2100 | F13: =+E13/$E$22 -> 0.016820027 | G13: No | H13: =+E13 -> 2100 | K13: =SUM(H13:J13) -> 2100
A14: O 050-72-1499 | B14: Wanda Vivieca 1083 Vista Haven Circle, Apt 204 Orlando, FL 32825 | C14: Trades | D14: 914 | E14: 750 | F14: =+E14/$E$22 -> 0.0060071524 | G14: No | J14: 750 | K14: =SUM(H14:J14) -> 750
A15: S 36-5114192 | B15: Orange Painting Services 13014 N Dale Mabry Hwy Suite 127 Tampa, FL 33618 | C15: Trades | D15: 914 | E15: 26496.82 | F15: =+E15/$E$22 -> 0.21222725 | G15: Yes | H15: =+C38*0.4 -> 10992.764 | I15: =+C38*0.35 -> 9618.6685 | J15: =+C38*0.25 -> 6870.4775 | K15: =SUM(H15:J15) -> 27481.91
A16: O 93-3732800 | B16: Gruntle, LLC 39232 9th Avenue Zephyrhills, FL 33542 | C16: Trades | D16: 914 | E16: 39498.11 | F16: =+E16/$E$22 -> 0.31636155 | G16: No | H16: =+E16*0.4 -> 15799.244 | I16: =+E16*0.35 -> 13824.338 | J16: =+E16*0.25 -> 9874.5275 | K16: =SUM(H16:J16) -> 39498.11
A17: S 84-3961344 | B17: Authentic Air Solutions LLC 10948 Keys Gate Drive Riverview, FL 33579 | C17: Trades | D17: 914 | E17: 11790 | F17: =+E17/$E$22 -> 0.094432435 | G17: Yes | H17: =+E17*0.5 -> 5895 | I17: =+E17*0.25 -> 2947.5 | J17: =+E17*0.25 -> 2947.5 | K17: =SUM(H17:J17) -> 11790
A18: O 83-3164510 | B18: Sunny R&R LLC 1922 Hillcrest St Orlando, FL 32803 | C18: Trades | D18: 914 | E18: 28601 | F18: =+E18/$E$22 -> 0.22908075 | G18: No | H18: =+E18*0.5 -> 14300.5 | I18: =+E18*0.25 -> 7150.25 | J18: =+E18*0.25 -> 7150.25 | K18: =SUM(H18:J18) -> 28601
A19: S 84-2385721 | B19: Tronco's Land of Florida LLC 9202 Celebration Ct Tampa, FL 33647 | C19: Trades | D19: 914 | E19: 800 | F19: =+E19/$E$22 -> 0.0064076292 | G19: Yes | H19: =+E19 -> 800 | K19: =SUM(H19:J19) -> 800
B20: 104 Electrical | E20: 8000 | F20: =+E20/$E$22 -> 0.064076292 | H20: =+E20*0.5 -> 4000 | I20: =+E20*0.25 -> 2000 | J20: =+E20*0.25 -> 2000 | K20: =SUM(H20:J20) -> 8000
B21: Termites | E21: 4600 | F21: =+E21/$E$22 -> 0.036843868 | J21: 4600 | K21: =SUM(H21:J21) -> 4600
A22: Total ALL Subcontract / Supplier Utilization | E22: =SUM(E10:E21) -> 124851.17 | H22: =SUM(H10:H21) -> 56102.748 | I22: =SUM(I10:I21) -> 35540.757 | J22: =SUM(J10:J21) -> 34192.755 | K22: =SUM(K10:K21) -> 125836.26
A23: Total SLBE Utilization | E23: =+E12+E15+E17+E19 -> 39746.82 | H23: =+H22*0.1881 -> 10552.927 | I23: =+I22*0.1881 -> 6685.2164 | J23: =+J22*0.1881 -> 6431.6572 | K23: =SUM(H23:J23) -> 23669.801
A24: Percent SLBE Utilization of Total Bid/Proposal Amt. | E24: =+F12+F15+F17+F19 -> 0.3183536 | H24: =SUM(H22:H23) -> 66655.675 | I24: =SUM(I22:I23) -> 42225.973 | J24: =SUM(J22:J23) -> 40624.412 | K24: =SUM(K22:K23) -> 149506.06
D26: 0.1881 | E26: =(E22-E10-E11)*D26 -> 23191.964 | H26: =+H24/K24 -> 0.44583928 | I26: =+I24/K24 -> 0.28243653 | J26: =+J24/K24 -> 0.27172418
C27: Gordian | E27: =+E22+E26 -> 148043.13
C28: 148600
B32: Orange Painting | E32: Gruntle
B33: Soffit & Fascia | C33: =11015.09-495 -> 10520.09 | E33: Windows | F33: 17785.11
B34: Exterior Paintng | C34: =6094-390-780 -> 4924 | E34: Spray Insulation | F34: 8000
B35: Flooring | C35: 11242.82 | E35: Ceiling | F35: 9000
B36: PP | C36: 300 | E36: other | F36: 4750
B37: Dumpster | C37: 495
C38: =SUM(C33:C37) -> 27481.91 | F38: =SUM(F33:F37) -> 39535.11
C39: =+E15-C38 -> -985.09
A45: O | B45: Hughes Exterminators 1781 W Hillsborough Ave Tampa, FL 33603 | 813-884-1555 | C45: Trades | D45: 914 | E45: 5126 | F45: 0.041 | G45: No | I45: 4600 | K45: =SUM(H45:J45) -> 4600
A46: O 59-3511620 | B46: JDP Electric, Inc 4183 E Hillsborough Ave Tampa, FL 33610 | C46: Trades | D46: 914 | E46: 7983 | F46: 0.0638 | G46: No | K46: =SUM(H46:J46) -> 0
A47: S 83-3172823 | B47: KapCook Enterprises LLC 10810 Boyette Road 148 Riverview, FL 33569 | C47: Supplier | D47: 912-77 | E47: 860 | F47: 0.0069 | G47: Yes | H47: 0 | I47: 0 | J47: 0 | K47: =SUM(H47:J47) -> 0

Sheet DMI20
A2: Page 1 of 2 – DMI Solicited/Utilized Schedules City of Tampa – Schedule of All To-Be-Utilized Sub-(Contractors/Consultants/Suppliers) (DMI 20 Form) Contract No.: Contract Name: Company Name: Lionize Construction Address: 38439 5th Avenue, PMB 128, Zephyrhills, FL 33542 Federal ID: Phone: 407-466-3689 Fax: Email: Check applicable box(es). Detailed Instructions for completing this form are on page 4 of 4. See attached list of additional Firms Utilized and all supplemental information (List must comply with this form)
A3: Note: Form DMI-20 must list ALL subcontractors To-Be-Utilized. No Subcontracting/consulting (of any kind) will be performed on this contract. No Firms are listed to be utilized because: NIGP Code General Categories: Buildings = 909, General = 912, Heavy = 913, Trades = 914, Architects = 906, Engineers & Surveyors = 925, Supplier = 912-77 Enter “S” for firms Certified as Small Local Business Enterprises: “O” for Other Non-Certified
B4: S = SLBE O =Neither | D4: Company Name Address Phone, Fax, Email | F4: Trade, Services or Materials NIGP Code Listed above | H4: $ Amount of Quote. Letter of Intent (LOI) if available | I4: Percent of Scope or Contract %
B5: Federal ID | N5: PROJ TOTAL
D6: City of Tampa - Development & Growth | F6: 909 | H6: 414.22 | I6: =H6/$N$6 -> 0.0033113067 | N6: =+Rehab!F45 -> 125092.61
D8: Hillsborough | F8: 909 | H8: 13.46 | I8: =H8/$N$6 -> 0.00010760028
B10: S | D10: Ambit Engineering, LLC 3848 Sun City Center Blvd Ste 104 PMB 1027 Ruskin, Florida 33573 | F10: 925 | H10: 660 | I10: =H10/$N$6 -> 0.005276091
B11: 86-3095308
B12: O | D12: JM Drafting Services LLC 9944 Warm Stone Street Thonotosassa, Fl 33592 | F12: 925 | H12: 2100 | I12: =H12/$N$6 -> 0.016787562
B13: 88-1849350
B14: S | D14: KapCook Enterprises LLC 10810 Boyette Road 148 Riverview, FL 33569 | F14: 912-77 | H14: =+Rehab!F12 -> 860 | I14: =H14/$N$6 -> 0.0068749065
B15: 83-3172823
B16: O | D16: Wanda Vivieca 1083 Vista Haven Circle, Apt 204 Orlando, FL 32825 | F16: 914 | H16: 750 | I16: =H16/$N$6 -> 0.005995558
B17: 050-72-1499
B18: O | D18: Hughes Exterminators 1781 W Hillsborough Ave Tampa, FL 33603 813-884-1555 | F18: 914 | H18: 5126 | I18: =H18/$N$6 -> 0.04097764
O19: =SUM(H6:H19) -> 9923.68
A20: Total ALL Subcontract / Supplier Utilization $126830.10 Total SLBE Utilization $40,794.82 Percent SLBE Utilization of Total Bid/Proposal Amt. 32.16% It is hereby certified that the following information is a true and accurate account of utilization for sub-contracting opportunities on this Contract. Signed: Name/Title: Date:
A23: Page 1 of 2 – DMI Solicited/Utilized Schedules City of Tampa – Schedule of All To-Be-Utilized Sub-(Contractors/Consultants/Suppliers) (DMI 20 Form) Contract No.: Contract Name: Company Name: Lionize Construction Address: 38439 5th Avenue, PMB 128, Zephyrhills, FL 33542 Federal ID: Phone: 407-466-3689 Fax: Email: Check applicable box(es). Detailed Instructions for completing this form are on page 4 of 4. See attached list of additional Firms Utilized and all supplemental information (List must comply with this form)
B24: S = SLBE O =Neither | D24: Company Name Address Phone, Fax, Email | F24: Trade, Services or Materials NIGP Code Listed above | H24: $ Amount of Quote. Letter of Intent (LOI) if available | I24: Percent of Scope or Contract %
B25: Federal ID
B26: S | D26: Orange Painting Services 13014 N Dale Mabry Hwy Suite 127 Tampa, FL 33618 | F26: 914 | H26: =+Rehab!G4 -> 26496.82 | I26: =H26/$N$6 -> 0.21181763
B27: 36-5114192
B28: O | D28: Gruntle, LLC 39232 9th Avenue Zephyrhills, FL 33542 | F28: 914 | H28: =+Rehab!G6 -> 39498.11 | I28: =H28/$N$6 -> 0.31575095
B29: 93-3732800
B30: S | D30: Authentic Air Solutions LLC 10948 Keys Gate drive Riverview, FL 33579 | F30: 914 | H30: 11790 | I30: =H30/$N$6 -> 0.094250172
B31: 84-3961344
B32: O | D32: Sunny R&R LLC 1922 Hillcrest St Orlando, FL 32803 | F32: 914 | H32: 28601 | I32: =H32/$N$6 -> 0.22863861
B33: 83-3164510
B34: O | D34: JDP Electric, Inc 4183 E Hillsborough Ave Tampa, FL 33610 | F34: 914 | H34: 7983 | I34: =H34/$N$6 -> 0.063816719
B35: 59-3511620
B36: S | D36: Tronco's Land of Florida LLC 9202 Celebration Ct Tampa, Fl 33647 | F36: 914 | H36: 800 | I36: =H36/$N$6 -> 0.0063952619
B37: 84-2385721 | O37: =+Rehab!F45 -> 125092.61
I38: =H38/N6 -> 0 | O38: sum | P38: discrepancy
N39: =SUM(H26:H39) -> 115168.93 | O39: =+N39+O19 -> 125092.61 | P39: =+O37-O39 -> 0
A40: Total ALL Subcontract / Supplier Utilization $125,092.61 Total SLBE Utilization $48,589.82 Percent SLBE Utilization of Total Bid/Proposal Amt. 38.84% It is hereby certified that the following information is a true and accurate account of utilization for sub-contracting opportunities on this Contract. Signed: Name/Title: Date:
D42: SLBE Utilization | E42: Percent SLBE
D43: 48589.82 | E43: 0.38843078

Sheet Rehab
A2: PROJECT: | B2: CRA-25-883-0001
A3: LOCATION: | B3: 3610 E. Dr. MLK Jr. Boulevard | C3: 0.1881
F4: =SUM(F38,F39) -> 11790 | G4: =SUM(G23,G24,F28)+F13 -> 26496.82 | H4: orace
G5: =SUM(H21,H22) -> 28601 | H5: sunny
B6: 1. ENVIRONMENTAL TESTING & HAZARD REMEDIATION | G6: =+H29+H30+H31+H32+H33+H26 -> 39498.11 | H6: gruntle
B7: DIVISION 01 – GENERAL REQUIREMENTS | C7: Column1 | E7: Sub | F7: MBE | G7: SLBE | H7: Other
B8: PERMITTING: | C8: 858.17 | E8: Tamp | H8: 414.22
E9: hillsborouh | H9: 13.46
B10: Engineer permit | C10: 440 | E10: Ambit | F10: 660
B11: Site Plan | E11: JM Draftting | H11: 2100
B12: portable toylet | C12: 2048 | E12: KapCook Enterprises | F12: 860 | J12: 860
B13: Dump Truck Waste Management | C13: 2048 | E13: orange | F13: 1000 | J13: 188
B14: Final cleaning | C14: 750 | E14: Wanda | H14: =+C14 -> 750
B15: DIVISION 02 – EXISTING CONDITIONS
B16: Subterranean Termite Treatment for residential structure, main dwelling for existing infestation. | C16: 1200 | E16: Hudges | H16: =+C16 -> 1200
B17: Tent Fumigation for wood destroying organisms for residents main dwelling slab for existing infestation. | C17: 3926 | E17: Hudges | H17: =+C17 -> 3926
B18: 2. SITE WORK & EXTERIOR IMPROVEMENTS
B19: Tree Trimming: OAK TREE trimming and prunning | C19: 800 | E19: Troncoso | F19: =+C19 -> 800
B20: 6. ROOFING & EXTERIOR FINISHES (DIVISION 07)
B21: ROOF REPLACEMENT: | C21: 25800 | E21: Sunny Roofing | H21: =+C21 -> 25800
B22: Gutter | C22: 2801 | E22: Sunny Roofing | H22: =+C22 -> 2801
B23: Remove & Reinstall Vinyl Soffit & Fascia | C23: 8160 | E23: Orange Painting | G23: =+C23 -> 8160
B24: Exterior Painting | C24: 6094 | E24: Orange Painting | G24: =+C24 -> 6094
B25: 7. DOORS, WINDOWS & GLAZING (DIVISION 08)
B26: 08 40 00 – Windows | C26: 17785.11 | E26: Gruntle | H26: =+C26 -> 17785.11
B27: 8. INTERIOR FINISHES (DIVISION 09)
B28: Flooring | C28: 11242.82 | E28: Orange Painting | F28: =+C28 -> 11242.82
B29: Insulation - Close Cell | C29: 8500 | E29: Gruntle | H29: =+C29 -> 8500
B30: Remove Ceiling Drywall and Insulation | C30: 2293 | E30: Gruntle | H30: =+C30+188 -> 2481
B31: Ceiling on all house: Tape plaster, Flat ceiling, Primer, Paint ceiling | C31: 9172 | E31: Gruntle | H31: =+C31 -> 9172
B32: Supplies | C32: 4850 | E32: Gruntle | H32: 880
B33: Replace 2 Bathroom Toilet | C33: 409 | E33: Gruntle | H33: 680
B34: Replace Bathroom Vanity | C34: 0
B35: Replace Bathroom Mirror | C35: 0
B36: 9. MECHANICAL, PLUMBING & HVAC (DIVISION 20-23)
B37: DIVISION 23 – HVAC
B38: 2.5 TON 14.4 SEER2 ALLIED HEAT PUMP SPLIT UNIT INSTALLATION (HORIZONTAL) | C38: 5395 | E38: Athentic Air | F38: 5395
B39: 4 TON 14.7 SEER2 ALLIED HEAT PUMP SPLIT UNIT INSTALLATION (VERTICAL) | C39: 6395 | E39: Athentic Air | F39: 6395
B40: 10. ELECTRICAL (DIVISION 26)
B41: ELECTRICAL: | C41: 7911 | E41: JDP | F41: 7983
...

Sheet test
D2: 0.1881
B4: 1. ENVIRONMENTAL TESTING & HAZARD REMEDIATION | I4: Sub | J4: MBE | K4: SLBE | L4: Other
B5: Lead Testing | C5: 1150 | D5: =+C5*D2 -> 216.315 | E5: =SUM(C5:D5) -> 1366.315 | F5: =+E5 -> 1366.315 | G5: 1400 | H5: =+G5-F5 -> 33.685 | I5: AirMD | L5: =+C5 -> 1150 | M5: =+C5-J5-K5-L5 -> 0
K9: Percent SLBE
I10: SLBE Utilization | J10: 0 | K10: =+J10/J12 -> 0
I11: Other | J11: =+L5 -> 1150 | K11: =+J11/J12 -> 1
J12: =SUM(J10:J11) -> 1150 | K12: =SUM(K10:K11) -> 1

Sheet EvA
A2: PROJECT: | B2: CRA-25-883-0001
A3: LOCATION: | B3: 3610 E. Dr. MLK Jr. Boulevard | C3: 0.1881
B6: 1. ENVIRONMENTAL TESTING & HAZARD REMEDIATION
B7: Lead Testing | C7: 1150 | D7: =C7*$C$3 -> 216.315 | E7: =SUM(C7:D7) -> 1366.315 | F7: =+E7 -> 1366.315 | G7: 1400 | H7: =+G7-F7 -> 33.685 | I7: AirMD | L7: =+C7 -> 1150 | M7: =+C7-J7-K7-L7 -> 0
B10: DIVISION 01 – GENERAL REQUIREMENTS | I10: Sub | J10: MBE | K10: SLBE | L10: Other | M10: Balance
B11: PERMITTING: | C11: 858.17 | E11: =+C11+D11 -> 858.17 | F11: =+E11 -> 858.17 | I11: Tamp | L11: =+C11 -> 858.17 | M11: =+C11-J11-K11-L11 -> 0
B12: Engineer permit | C12: 440 | D12: =+C12*$C$3 -> 82.764 | E12: =+C12+D12 -> 522.764 | F12: =+E12 -> 522.764
B13: Dump Truck Waste Management (Dumpsters & Cleaning) 2,800.00 Stamplia | C13: 2048 | D13: =+C13*$C$3 -> 385.2288 | E13: =+C13+D13 -> 2433.2288 | F13: =+E13 -> 2433.2288 | I13: MobileDump | J13: 1200 | M13: =+C13-J13-K13-L13 -> 848
B14: Final cleaning | C14: 750 | D14: =+C14*$C$3 -> 141.075 | E14: =+C14+D14 -> 891.075 | F14: =+E14 -> 891.075 | I14: Wanda | L14: =+C14 -> 750 | M14: =+C14-J14-K14-L14 -> 0
B15: DIVISION 02 – EXISTING CONDITIONS
B16: Subterranean Termite Treatment for residential structure, main dwelling for existing infestation. | C16: 1200 | D16: =+C16*$C$3 -> 225.72 | E16: =SUM(C16:D16) -> 1425.72 | F16: =+E16 -> 1425.72 | I16: Hudges | L16: =+C16 -> 1200 | M16: =+C16-J16-K16-L16 -> 0
B17: Tent Fumigation for wood destroying organisms for residents main dwelling slab for existing infestation. | C17: 3926 | D17: =+C17*$C$3 -> 738.4806 | E17: =SUM(C17:D17) -> 4664.4806 | F17: =+E17 -> 4664.4806 | I17: Hudges | L17: =+C17 -> 3926 | M17: =+C17-J17-K17-L17 -> 0
B18: 2. SITE WORK & EXTERIOR IMPROVEMENTS
B19: Tree Trimming: OAK TREE trimming and prunning | C19: 800 | D19: =+C19*$C$3 -> 150.48 | E19: =SUM(C19:D19) -> 950.48 | F19: =+E19 -> 950.48 | I19: Troncoso | J19: =+C19 -> 800
B20: 6. ROOFING & EXTERIOR FINISHES (DIVISION 07)
B21: ROOF REPLACEMENT: | C21: 25800 | D21: =C21*$C$3 -> 4852.98 | E21: =SUM(C21:D21) -> 30652.98 | F21: =+E21 -> 30652.98 | I21: Sunny Roofing | L21: =+C21 -> 25800 | M21: =+C21-J21-K21-L21 -> 0
B22: Gutter | C22: 2801 | D22: =C22*$C$3 -> 526.8681 | E22: =SUM(C22:D22) -> 3327.8681 | F22: =+E22 -> 3327.8681 | I22: Sunny Roofing | L22: =+C22 -> 2801 | M22: =+C22-J22-K22-L22 -> 0
B23: Remove & Reinstall Vinyl Soffit & Fascia | C23: 8160 | D23: =C23*$C$3 -> 1534.896 | E23: =SUM(C23:D23) -> 9694.896 | F23: =+E23 -> 9694.896 | I23: Orange Painting | K23: =+C23 -> 8160 | M23: =+C23-J23-K23-L23 -> 0
B24: Exterior Painting | C24: 6094 | D24: =+C24*$C$3 -> 1146.2814 | E24: =+C24+D24 -> 7240.2814 | F24: =+E24 -> 7240.2814 | I24: Orange Painting | K24: =+C24 -> 6094 | M24: =+C24-J24-K24-L24 -> 0
B25: 7. DOORS, WINDOWS & GLAZING (DIVISION 08)
B26: 08 40 00 – Windows | C26: 17785.11 | D26: =C26*$C$3 -> 3345.3792 | E26: =SUM(C26:D26) -> 21130.489 | F26: =+E26 -> 21130.489 | I26: 3D | L26: 10386.07 | M26: =+C26-J26-K26-L26 -> 7399.04 | O26: 22158
B27: 8. INTERIOR FINISHES (DIVISION 09)
B28: Flooring | C28: 11242.82 | D28: =+C28*$C$3 -> 2114.7744 | E28: =+C28+D28 -> 13357.594 | F28: =+E28 -> 13357.594 | I28: Orange Painting | J28: 10115.4 | M28: =+C28-J28-K28-L28 -> 1127.42
B29: Insulation - Close Cell | C29: 8500 | D29: =+C29*$C$3 -> 1598.85 | E29: =+C29+D29 -> 10098.85 | F29: =+E29 -> 10098.85 | I29: Gruntle | L29: 5000 | M29: =+C29-J29-K29-L29 -> 3500
B30: Remove Ceiling Drywall and Insulation | C30: 2293 | D30: =+C30*$C$3 -> 431.3133 | E30: =+C30+D30 -> 2724.3133 | F30: =+E30 -> 2724.3133
B31: Ceiling on all house: Tape plaster, Flat ceiling, Primer, Paint ceiling | C31: 9172 | D31: =+C31*$C$3 -> 1725.2532 | E31: =+C31+D31 -> 10897.253 | F31: =+E31 -> 10897.253 | I31: Gruntle | L31: =9172+2293 -> 11465 | M31: =+C31-J31-K31-L31 -> -2293 | N31: Nancy
B32: Interior Painting | C32: 4850 | D32: =+C32*$C$3 -> 912.285 | E32: =+C32+D32 -> 5762.285 | F32: =+E32 -> 5762.285 | G32: =+F31+F32 -> 16659.538 | I32: Gruntle | L32: 4850 | M32: =+C32-J32-K32-L32 -> 0 | N32: Nancy
B33: Replace 2 Bathroom Toilet | C33: 409 | D33: =+C33*$C$3 -> 76.9329 | E33: =+C33+D33 -> 485.9329 | F33: =+E33 -> 485.9329 | I33: Gruntle | L33: 480 | M33: =+C33-J33-K33-L33 -> -71 | N33: Nancy
B34: Replace Bathroom Vanity | C34: 0 | D34: =+C34*$C$3 -> 0 | E34: =+C34+D34 -> 0 | F34: =+E34 -> 0
B35: Replace Bathroom Mirror | C35: 0 | D35: =+C35*$C$3 -> 0 | E35: =+C35+D35 -> 0 | F35: =+E35 -> 0
B36: 9. MECHANICAL, PLUMBING & HVAC (DIVISION 20-23)
B37: DIVISION 23 – HVAC
B38: 2.5 TON 14.4 SEER2 ALLIED HEAT PUMP SPLIT UNIT INSTALLATION (HORIZONTAL) | C38: 5395 | D38: =+C38*$C$3 -> 1014.7995 | E38: =+C38+D38 -> 6409.7995 | F38: =+E38 -> 6409.7995 | I38: Athentic Air | J38: 5395 | M38: =+C38-J38-K38-L38 -> 0
B39: 4 TON 14.7 SEER2 ALLIED HEAT PUMP SPLIT UNIT INSTALLATION (VERTICAL) | C39: 6395 | D39: =+C39*$C$3 -> 1202.8995 | E39: =+C39+D39 -> 7597.8995 | F39: =+E39 -> 7597.8995 | G39: =+F38+F39 -> 14007.699 | I39: Athentic Air | J39: 6395 | M39: =+C39-J39-K39-L39 -> 0
B40: 10. ELECTRICAL (DIVISION 26)
B41: ELECTRICAL: | C41: 7911 | D41: =+C41*$C$3 -> 1488.0591 | E41: =+C41+D41 -> 9399.0591 | F41: =+E41 -> 9399.0591 | I41: AIO | J41: =+C41 -> 7911 | M41: =+C41-J41-K41-L41 -> 0
C42: =SUM(C7:C41) -> 127980.1 | D42: =SUM(D7:D41) -> 23911.635 | E42: =SUM(E7:E41) -> 151891.74 | F42: =SUM(F7:F41) -> 151891.74 | J42: =SUM(J7:J41) -> 31816.4 | K42: =SUM(K7:K41) -> 14254 | L42: =SUM(L7:L41) -> 68666.24 | M42: =SUM(M7:M41) -> 10510.46
J43: =+J42/J44 -> 0.25402904 | K43: =+K42/J44 -> 0.11380703 | L43: =+L42/J44 -> 0.54824615
C44: =+F45-C42 -> 22019.9 | J44: =+J42+K42+L42+M42 -> 125247.1
C45: =+C44/C42 -> 0.17205722 | F45: 150000 | J45: =+F45-J44 -> 24752.9
...

Sheet CPM
A1: City of Tampa – Schedule of All To-Be-Utilized Sub-(Contractors/Consultants/Suppliers)
A2: Contract No.: | B2: 25-P-00039 | C2: Contract Name: | D2: Job Order for Residential Rehabilitation and Repair Services
A3: Company Name: | B3: Lionize Construction | C3: Address: | D3: 38439 5th Avenue, PMB 128, Zephyrhills, FL 33542
A4: Phone: | B4: 407-466-3689 | C4: Email: | D4: Luz@aioenterprise.com
A5: Property Address: | B5: 3610 E Dr Martin Luther King Jr Blvd, Tampa, FL 33610
A6: TASK | B6: ASSIGNED TO | C6: PROGRESS | D6: START | E6: END
A7: Sofit & Fascia | B7: Orange Painting Services
A8: Roofing & Gutters | B8: Sunny R&R LLC
A9: Remove Ceiling & Insulation | B9: Gruntle, LLC
A10: Install Spray Insulation | B10: Gruntle, LLC
A11: Install new Ceiling | B11: Gruntle, LLC
A12: Windows | B12: Gruntle, LLC
A13: Flooring | B13: Orange Painting Services
A14: Exterior Painting | B14: Orange Painting Services
A15: Cleaning | B15: W. Endless Solutions
A16: HVAc | B16: Authentic Air Solutions LLC
A17: Electrical | B17: 104 Electrical
A18: Termites | B18: Termites
